[2022-12-17T11:03:03.949+0000] {taskinstance.py:1087} INFO - Dependencies all met for <TaskInstance: titanic_etl_pipeline.load_to_postgres manual__2022-12-16T23:11:35.228323+00:00 [queued]>
[2022-12-17T11:03:03.962+0000] {taskinstance.py:1087} INFO - Dependencies all met for <TaskInstance: titanic_etl_pipeline.load_to_postgres manual__2022-12-16T23:11:35.228323+00:00 [queued]>
[2022-12-17T11:03:03.962+0000] {taskinstance.py:1283} INFO - 
--------------------------------------------------------------------------------
[2022-12-17T11:03:03.964+0000] {taskinstance.py:1284} INFO - Starting attempt 1 of 2
[2022-12-17T11:03:03.964+0000] {taskinstance.py:1285} INFO - 
--------------------------------------------------------------------------------
[2022-12-17T11:03:03.986+0000] {taskinstance.py:1304} INFO - Executing <Task(PythonOperator): load_to_postgres> on 2022-12-16 23:11:35.228323+00:00
[2022-12-17T11:03:03.991+0000] {standard_task_runner.py:55} INFO - Started process 1865 to run task
[2022-12-17T11:03:03.996+0000] {standard_task_runner.py:82} INFO - Running: ['***', 'tasks', 'run', 'titanic_etl_pipeline', 'load_to_postgres', 'manual__2022-12-16T23:11:35.228323+00:00', '--job-id', '105', '--raw', '--subdir', 'DAGS_FOLDER/titanic_etl.py', '--cfg-path', '/tmp/tmp1a0xq9qu']
[2022-12-17T11:03:03.999+0000] {standard_task_runner.py:83} INFO - Job 105: Subtask load_to_postgres
[2022-12-17T11:03:04.076+0000] {task_command.py:389} INFO - Running <TaskInstance: titanic_etl_pipeline.load_to_postgres manual__2022-12-16T23:11:35.228323+00:00 [running]> on host 3b51f8facfba
[2022-12-17T11:03:04.283+0000] {taskinstance.py:1513} INFO - Exporting the following env vars:
AIRFLOW_CTX_DAG_OWNER=***
AIRFLOW_CTX_DAG_ID=titanic_etl_pipeline
AIRFLOW_CTX_TASK_ID=load_to_postgres
AIRFLOW_CTX_EXECUTION_DATE=2022-12-16T23:11:35.228323+00:00
AIRFLOW_CTX_TRY_NUMBER=1
AIRFLOW_CTX_DAG_RUN_ID=manual__2022-12-16T23:11:35.228323+00:00
[2022-12-17T11:03:04.287+0000] {taskinstance.py:1772} ERROR - Task failed with exception
Traceback (most recent call last):
  File "/home/airflow/.local/lib/python3.7/site-packages/airflow/operators/python.py", line 175, in execute
    return_value = self.execute_callable()
  File "/home/airflow/.local/lib/python3.7/site-packages/airflow/operators/python.py", line 192, in execute_callable
    return self.python_callable(*self.op_args, **self.op_kwargs)
  File "/opt/airflow/dags/titanic_etl.py", line 87, in load_to_postgres
    df = pd.read_csv(filename)
  File "/home/airflow/.local/lib/python3.7/site-packages/pandas/util/_decorators.py", line 311, in wrapper
    return func(*args, **kwargs)
  File "/home/airflow/.local/lib/python3.7/site-packages/pandas/io/parsers/readers.py", line 586, in read_csv
    return _read(filepath_or_buffer, kwds)
  File "/home/airflow/.local/lib/python3.7/site-packages/pandas/io/parsers/readers.py", line 482, in _read
    parser = TextFileReader(filepath_or_buffer, **kwds)
  File "/home/airflow/.local/lib/python3.7/site-packages/pandas/io/parsers/readers.py", line 811, in __init__
    self._engine = self._make_engine(self.engine)
  File "/home/airflow/.local/lib/python3.7/site-packages/pandas/io/parsers/readers.py", line 1040, in _make_engine
    return mapping[engine](self.f, **self.options)  # type: ignore[call-arg]
  File "/home/airflow/.local/lib/python3.7/site-packages/pandas/io/parsers/c_parser_wrapper.py", line 51, in __init__
    self._open_handles(src, kwds)
  File "/home/airflow/.local/lib/python3.7/site-packages/pandas/io/parsers/base_parser.py", line 229, in _open_handles
    errors=kwds.get("encoding_errors", "strict"),
  File "/home/airflow/.local/lib/python3.7/site-packages/pandas/io/common.py", line 707, in get_handle
    newline="",
FileNotFoundError: [Errno 2] No such file or directory: '/opt/airflow/data/titanic_transformed.csv'
[2022-12-17T11:03:04.389+0000] {taskinstance.py:1327} INFO - Marking task as UP_FOR_RETRY. dag_id=titanic_etl_pipeline, task_id=load_to_postgres, execution_date=20221216T231135, start_date=20221217T110303, end_date=20221217T110304
[2022-12-17T11:03:04.411+0000] {standard_task_runner.py:105} ERROR - Failed to execute job 105 for task load_to_postgres ([Errno 2] No such file or directory: '/opt/airflow/data/titanic_transformed.csv'; 1865)
[2022-12-17T11:03:04.450+0000] {local_task_job.py:159} INFO - Task exited with return code 1
[2022-12-17T11:03:04.477+0000] {taskinstance.py:2582} INFO - 0 downstream tasks scheduled from follow-on schedule check
