[2022-12-16T23:09:55.159+0000] {taskinstance.py:1087} INFO - Dependencies all met for <TaskInstance: titanic_etl_pipeline.create_dashboard_task manual__2022-12-16T22:48:58.965765+00:00 [queued]>
[2022-12-16T23:09:55.177+0000] {taskinstance.py:1087} INFO - Dependencies all met for <TaskInstance: titanic_etl_pipeline.create_dashboard_task manual__2022-12-16T22:48:58.965765+00:00 [queued]>
[2022-12-16T23:09:55.178+0000] {taskinstance.py:1283} INFO - 
--------------------------------------------------------------------------------
[2022-12-16T23:09:55.185+0000] {taskinstance.py:1284} INFO - Starting attempt 2 of 2
[2022-12-16T23:09:55.186+0000] {taskinstance.py:1285} INFO - 
--------------------------------------------------------------------------------
[2022-12-16T23:09:55.217+0000] {taskinstance.py:1304} INFO - Executing <Task(PythonOperator): create_dashboard_task> on 2022-12-16 22:48:58.965765+00:00
[2022-12-16T23:09:55.225+0000] {standard_task_runner.py:55} INFO - Started process 327 to run task
[2022-12-16T23:09:55.231+0000] {standard_task_runner.py:82} INFO - Running: ['***', 'tasks', 'run', 'titanic_etl_pipeline', 'create_dashboard_task', 'manual__2022-12-16T22:48:58.965765+00:00', '--job-id', '90', '--raw', '--subdir', 'DAGS_FOLDER/titanic_etl.py', '--cfg-path', '/tmp/tmp6v286hvu']
[2022-12-16T23:09:55.235+0000] {standard_task_runner.py:83} INFO - Job 90: Subtask create_dashboard_task
[2022-12-16T23:09:55.362+0000] {task_command.py:389} INFO - Running <TaskInstance: titanic_etl_pipeline.create_dashboard_task manual__2022-12-16T22:48:58.965765+00:00 [running]> on host 14c90533c456
[2022-12-16T23:09:55.531+0000] {taskinstance.py:1513} INFO - Exporting the following env vars:
AIRFLOW_CTX_DAG_OWNER=***
AIRFLOW_CTX_DAG_ID=titanic_etl_pipeline
AIRFLOW_CTX_TASK_ID=create_dashboard_task
AIRFLOW_CTX_EXECUTION_DATE=2022-12-16T22:48:58.965765+00:00
AIRFLOW_CTX_TRY_NUMBER=2
AIRFLOW_CTX_DAG_RUN_ID=manual__2022-12-16T22:48:58.965765+00:00
[2022-12-16T23:09:55.583+0000] {logging_mixin.py:137} INFO - Dash is running on http://127.0.0.1:8050/
[2022-12-16T23:09:55.583+0000] {dash.py:1968} INFO - Dash is running on http://127.0.0.1:8050/

[2022-12-16T23:09:55.608+0000] {logging_mixin.py:137} INFO -  * Serving Flask app '***'
[2022-12-16T23:09:55.609+0000] {logging_mixin.py:137} INFO -  * Debug mode: off
[2022-12-16T23:09:55.610+0000] {_internal.py:224} INFO - [31m[1mWARNING: This is a development server. Do not use it in a production deployment. Use a production WSGI server instead.[0m
 * Running on http://127.0.0.1:8050
[2022-12-16T23:09:55.611+0000] {_internal.py:224} INFO - [33mPress CTRL+C to quit[0m
[2022-12-16T23:16:46.590+0000] {local_task_job.py:224} WARNING - State of this instance has been externally set to None. Terminating instance.
[2022-12-16T23:16:46.594+0000] {process_utils.py:133} INFO - Sending Signals.SIGTERM to group 327. PIDs of all processes in the group: [327]
[2022-12-16T23:16:46.594+0000] {process_utils.py:84} INFO - Sending the signal Signals.SIGTERM to group 327
[2022-12-16T23:16:46.595+0000] {taskinstance.py:1483} ERROR - Received SIGTERM. Terminating subprocesses.
[2022-12-16T23:16:46.611+0000] {taskinstance.py:1772} ERROR - Task failed with exception
Traceback (most recent call last):
  File "/home/airflow/.local/lib/python3.7/site-packages/airflow/operators/python.py", line 175, in execute
    return_value = self.execute_callable()
  File "/home/airflow/.local/lib/python3.7/site-packages/airflow/operators/python.py", line 192, in execute_callable
    return self.python_callable(*self.op_args, **self.op_kwargs)
  File "/opt/airflow/dags/titanic_etl.py", line 84, in create_dashboard
    app.run_server()
  File "/home/airflow/.local/lib/python3.7/site-packages/dash/dash.py", line 2133, in run_server
    self.run(*args, **kwargs)
  File "/home/airflow/.local/lib/python3.7/site-packages/dash/dash.py", line 1980, in run
    self.server.run(host=host, port=port, debug=debug, **flask_run_options)
  File "/home/airflow/.local/lib/python3.7/site-packages/flask/app.py", line 1188, in run
    run_simple(t.cast(str, host), port, self, **options)
  File "/home/airflow/.local/lib/python3.7/site-packages/werkzeug/serving.py", line 1098, in run_simple
    srv.serve_forever()
  File "/home/airflow/.local/lib/python3.7/site-packages/werkzeug/serving.py", line 741, in serve_forever
    super().serve_forever(poll_interval=poll_interval)
  File "/usr/local/lib/python3.7/socketserver.py", line 232, in serve_forever
    ready = selector.select(poll_interval)
  File "/usr/local/lib/python3.7/selectors.py", line 415, in select
    fd_event_list = self._selector.poll(timeout)
  File "/home/airflow/.local/lib/python3.7/site-packages/airflow/models/taskinstance.py", line 1485, in signal_handler
    raise AirflowException("Task received SIGTERM signal")
airflow.exceptions.AirflowException: Task received SIGTERM signal
[2022-12-16T23:16:46.673+0000] {taskinstance.py:1327} INFO - Marking task as FAILED. dag_id=titanic_etl_pipeline, task_id=create_dashboard_task, execution_date=20221216T224858, start_date=20221216T230955, end_date=20221216T231646
[2022-12-16T23:16:46.711+0000] {standard_task_runner.py:105} ERROR - Failed to execute job 90 for task create_dashboard_task ((psycopg2.errors.ForeignKeyViolation) insert or update on table "task_fail" violates foreign key constraint "task_fail_ti_fkey"
DETAIL:  Key (dag_id, task_id, run_id, map_index)=(titanic_etl_pipeline, create_dashboard_task, manual__2022-12-16T22:48:58.965765+00:00, -1) is not present in table "task_instance".

[SQL: INSERT INTO task_fail (task_id, dag_id, run_id, map_index, start_date, end_date, duration) VALUES (%(task_id)s, %(dag_id)s, %(run_id)s, %(map_index)s, %(start_date)s, %(end_date)s, %(duration)s) RETURNING task_fail.id]
[parameters: {'task_id': 'create_dashboard_task', 'dag_id': 'titanic_etl_pipeline', 'run_id': 'manual__2022-12-16T22:48:58.965765+00:00', 'map_index': -1, 'start_date': datetime.datetime(2022, 12, 16, 23, 9, 55, 160830, tzinfo=Timezone('UTC')), 'end_date': datetime.datetime(2022, 12, 16, 23, 16, 46, 672451, tzinfo=Timezone('UTC')), 'duration': 411}]
(Background on this error at: https://sqlalche.me/e/14/gkpj); 327)
[2022-12-16T23:16:46.728+0000] {process_utils.py:79} INFO - Process psutil.Process(pid=327, status='terminated', exitcode=1, started='23:09:54') (327) terminated with exit code 1
