[2022-12-16T21:37:20.868+0000] {taskinstance.py:1087} INFO - Dependencies all met for <TaskInstance: titanic_etl_pipeline.extract_dataset manual__2022-12-16T21:37:17.306306+00:00 [queued]>
[2022-12-16T21:37:20.903+0000] {taskinstance.py:1087} INFO - Dependencies all met for <TaskInstance: titanic_etl_pipeline.extract_dataset manual__2022-12-16T21:37:17.306306+00:00 [queued]>
[2022-12-16T21:37:20.904+0000] {taskinstance.py:1283} INFO - 
--------------------------------------------------------------------------------
[2022-12-16T21:37:20.905+0000] {taskinstance.py:1284} INFO - Starting attempt 1 of 2
[2022-12-16T21:37:20.906+0000] {taskinstance.py:1285} INFO - 
--------------------------------------------------------------------------------
[2022-12-16T21:37:20.965+0000] {taskinstance.py:1304} INFO - Executing <Task(PythonOperator): extract_dataset> on 2022-12-16 21:37:17.306306+00:00
[2022-12-16T21:37:20.978+0000] {standard_task_runner.py:55} INFO - Started process 8708 to run task
[2022-12-16T21:37:20.990+0000] {standard_task_runner.py:82} INFO - Running: ['***', 'tasks', 'run', 'titanic_etl_pipeline', 'extract_dataset', 'manual__2022-12-16T21:37:17.306306+00:00', '--job-id', '46', '--raw', '--subdir', 'DAGS_FOLDER/titanic_etl.py', '--cfg-path', '/tmp/tmpbciaaqqh']
[2022-12-16T21:37:20.995+0000] {standard_task_runner.py:83} INFO - Job 46: Subtask extract_dataset
[2022-12-16T21:37:21.151+0000] {task_command.py:389} INFO - Running <TaskInstance: titanic_etl_pipeline.extract_dataset manual__2022-12-16T21:37:17.306306+00:00 [running]> on host ece303bd0765
[2022-12-16T21:37:21.348+0000] {taskinstance.py:1513} INFO - Exporting the following env vars:
AIRFLOW_CTX_DAG_OWNER=***
AIRFLOW_CTX_DAG_ID=titanic_etl_pipeline
AIRFLOW_CTX_TASK_ID=extract_dataset
AIRFLOW_CTX_EXECUTION_DATE=2022-12-16T21:37:17.306306+00:00
AIRFLOW_CTX_TRY_NUMBER=1
AIRFLOW_CTX_DAG_RUN_ID=manual__2022-12-16T21:37:17.306306+00:00
[2022-12-16T21:37:21.354+0000] {taskinstance.py:1772} ERROR - Task failed with exception
Traceback (most recent call last):
  File "/home/airflow/.local/lib/python3.7/site-packages/airflow/operators/python.py", line 175, in execute
    return_value = self.execute_callable()
  File "/home/airflow/.local/lib/python3.7/site-packages/airflow/operators/python.py", line 192, in execute_callable
    return self.python_callable(*self.op_args, **self.op_kwargs)
  File "/opt/airflow/dags/titanic_etl.py", line 14, in extract_clean
    df = pd.read_csv(filename)
  File "/home/airflow/.local/lib/python3.7/site-packages/pandas/util/_decorators.py", line 311, in wrapper
    return func(*args, **kwargs)
  File "/home/airflow/.local/lib/python3.7/site-packages/pandas/io/parsers/readers.py", line 586, in read_csv
    return _read(filepath_or_buffer, kwds)
  File "/home/airflow/.local/lib/python3.7/site-packages/pandas/io/parsers/readers.py", line 482, in _read
    parser = TextFileReader(filepath_or_buffer, **kwds)
  File "/home/airflow/.local/lib/python3.7/site-packages/pandas/io/parsers/readers.py", line 811, in __init__
    self._engine = self._make_engine(self.engine)
  File "/home/airflow/.local/lib/python3.7/site-packages/pandas/io/parsers/readers.py", line 1040, in _make_engine
    return mapping[engine](self.f, **self.options)  # type: ignore[call-arg]
  File "/home/airflow/.local/lib/python3.7/site-packages/pandas/io/parsers/c_parser_wrapper.py", line 51, in __init__
    self._open_handles(src, kwds)
  File "/home/airflow/.local/lib/python3.7/site-packages/pandas/io/parsers/base_parser.py", line 229, in _open_handles
    errors=kwds.get("encoding_errors", "strict"),
  File "/home/airflow/.local/lib/python3.7/site-packages/pandas/io/common.py", line 707, in get_handle
    newline="",
FileNotFoundError: [Errno 2] No such file or directory: 'titanic.csv'
[2022-12-16T21:37:21.386+0000] {taskinstance.py:1327} INFO - Marking task as UP_FOR_RETRY. dag_id=titanic_etl_pipeline, task_id=extract_dataset, execution_date=20221216T213717, start_date=20221216T213720, end_date=20221216T213721
[2022-12-16T21:37:21.423+0000] {standard_task_runner.py:105} ERROR - Failed to execute job 46 for task extract_dataset ([Errno 2] No such file or directory: 'titanic.csv'; 8708)
[2022-12-16T21:37:21.442+0000] {local_task_job.py:159} INFO - Task exited with return code 1
[2022-12-16T21:37:21.512+0000] {taskinstance.py:2582} INFO - 0 downstream tasks scheduled from follow-on schedule check
